Workbook

Sheet Dashboard
B2: GRIDx Smart Meter - 5-Year Financial Model
F3: 10,000 Meters | L3: Recommended
B5: 1. Input Parameters | L5: ="N$"&TEXT(INDEX($C$63:$G$63,1,$C$51)/1000000,"#,##0")&"M" -> N$338M | N5: ="N$"&TEXT(INDEX($C$62:$G$62,1,$C$51)/1000000,"#,##0")&"M" -> N$296M
B6: Rollout Scenario: | C6: 10,000 Meters | L6: Total Revenue | N6: Net Profit
L7: =TEXT(INDEX($C$64:$G$64,1,$C$51)*100,"0.0")&"%" -> 87.6% | N7: =TEXT(INDEX($C$65:$G$65,1,$C$51),"0.0")&" months" -> 4.2 months
B8: Hardware Price: | C8: N$5,500 | D8: /unit/yr | L8: Gross Margin | N8: Payback Period
B9: Installation: | C9: N$700 | D9: one-time
B10: Mfg Cost/Meter: | C10: ="N$"&TEXT(INDEX($C$53:$G$53,1,$C$51),"#,##0") -> N$1,700 | D10: per unit
B11: Personnel: | C11: N$748,800 | D11: /year
B12: Annual Revenue: | C12: ="N$"&TEXT(INDEX($C$52:$G$52,1,$C$51)*6620.8,"#,##0") -> N$66,208,000 | D12: /year
B13: Total 5Y Revenue: | C13: ="N$"&TEXT(INDEX($C$63:$G$63,1,$C$51),"#,##0") -> N$338,040,000 | D13: 5-year
B14: Total 5Y Costs: | C14: ="N$"&TEXT(INDEX($C$61:$G$61,1,$C$51),"#,##0") -> N$41,994,047 | D14: 5-year
B15: Net Profit: | C15: ="N$"&TEXT(INDEX($C$62:$G$62,1,$C$51),"#,##0") -> N$296,045,953 | D15: 5-year
B19: Metric | F19: Year 1 | G19: Year 2 | H19: Year 3 | I19: Year 4 | J19: Year 5 | L19: 5-Year Total
B20: Hardware Sales | F20: =INDEX($C$52:$G$52,1,$C$51)*5500 -> 55000000 | G20: =INDEX($C$52:$G$52,1,$C$51)*5500 -> 55000000 | H20: =INDEX($C$52:$G$52,1,$C$51)*5500 -> 55000000 | I20: =INDEX($C$52:$G$52,1,$C$51)*5500 -> 55000000 | J20: =INDEX($C$52:$G$52,1,$C$51)*5500 -> 55000000 | L20: =INDEX($C$52:$G$52,1,$C$51)*5500*5 -> 275000000
B21: Installation Fees | F21: =INDEX($C$52:$G$52,1,$C$51)*700 -> 7000000 | G21: 0 | H21: 0 | I21: 0 | J21: 0 | L21: =INDEX($C$52:$G$52,1,$C$51)*700 -> 7000000
B22: Service Revenue | F22: =INDEX($C$52:$G$52,1,$C$51)*1120.8 -> 11208000 | G22: =INDEX($C$52:$G$52,1,$C$51)*1120.8 -> 11208000 | H22: =INDEX($C$52:$G$52,1,$C$51)*1120.8 -> 11208000 | I22: =INDEX($C$52:$G$52,1,$C$51)*1120.8 -> 11208000 | J22: =INDEX($C$52:$G$52,1,$C$51)*1120.8 -> 11208000 | L22: =INDEX($C$52:$G$52,1,$C$51)*1120.8*5 -> 56040000
B23: Manufacturing Costs | F23: =-INDEX($C$54:$G$54,1,$C$51) -> -17899000 | G23: 0 | H23: 0 | I23: 0 | J23: 0 | L23: =-INDEX($C$54:$G$54,1,$C$51) -> -17899000
B24: Operating Costs | F24: =-INDEX($C$55:$G$55,1,$C$51)/5 -> -2168800 | G24: =-INDEX($C$55:$G$55,1,$C$51)/5 -> -2168800 | H24: =-INDEX($C$55:$G$55,1,$C$51)/5 -> -2168800 | I24: =-INDEX($C$55:$G$55,1,$C$51)/5 -> -2168800 | J24: =-INDEX($C$55:$G$55,1,$C$51)/5 -> -2168800 | L24: =-INDEX($C$55:$G$55,1,$C$51) -> -10844000
B25: Net Profit | F25: =F20+F21+F22+F23+F24 -> 53140200 | G25: =G20+G21+G22+G23+G24 -> 64039200 | H25: =H20+H21+H22+H23+H24 -> 64039200 | I25: =I20+I21+I22+I23+I24 -> 64039200 | J25: =J20+J21+J22+J23+J24 -> 64039200 | L25: =INDEX($C$62:$G$62,1,$C$51) -> 296045953
B27: Scenario Comparison
B28: Metric | F28: 3K | H28: 5K | J28: 10K | L28: 20K | N28: 50K
B29: 5-Year Revenue | F29: =C63 -> 101412000 | H29: =D63 -> 169020000 | J29: =E63 -> 338040000 | L29: =F63 -> 676080000 | N29: =G63 -> 1690200000
B30: 5-Year Costs | F30: =C61 -> 27375747 | H30: =D61 -> 32329547 | J30: =E61 -> 41994047 | L30: =F61 -> 64218047 | N30: =G61 -> 118425047
B31: Net Profit | F31: =C62 -> 74036253 | H31: =D62 -> 136690453 | J31: =E62 -> 296045953 | L31: =F62 -> 611861953 | N31: =G62 -> 1571774953
B32: Gross Margin | F32: =C64 -> 0.73005417 | H32: =D64 -> 0.80872354 | J32: =E64 -> 0.87577196 | L32: =F64 -> 0.90501413 | N32: =G64 -> 0.9299343
B33: Payback | F33: =C65 -> 7.6 | H33: =D65 -> 7.2 | J33: =E65 -> 4.2 | L33: =F65 -> 3.9 | N33: =G65 -> 3.5
C50: 3,000 Meters | D50: 5,000 Meters | E50: 10,000 Meters | F50: 20,000 Meters | G50: 50,000 Meters
C51: =MATCH($C$6,$C$50:$G$50,0) -> 3
C52: 3000 | D52: 5000 | E52: 10000 | F52: 20000 | G52: 50000
C53: 2000 | D53: 2000 | E53: 1700 | F53: 1700 | G53: 1462
C54: =Manufacturing!B16 -> 6269700 | D54: =Manufacturing!C16 -> 10449500 | E54: =Manufacturing!D16 -> 17899000 | F54: =Manufacturing!E16 -> 35798000 | G54: =Manufacturing!F16 -> 77595000
C55: ='Operating Costs'!B14 -> 8914000 | D55: ='Operating Costs'!C14 -> 9444000 | E55: ='Operating Costs'!D14 -> 10844000 | F55: ='Operating Costs'!E14 -> 13644000 | G55: ='Operating Costs'!F14 -> 21894000
C56: =Implementation!B9 -> 1500000 | D56: =Implementation!C9 -> 1500000 | E56: =Implementation!D9 -> 1500000 | F56: =Implementation!E9 -> 1500000 | G56: =Implementation!F9 -> 1500000
C57: =Equipment!B11 -> 1099000 | D57: =Equipment!C11 -> 1290000 | E57: =Equipment!D11 -> 1965000 | F57: =Equipment!E11 -> 3210000 | G57: =Equipment!F11 -> 6545000
C58: =Development!B14 -> 7851647 | D58: =Development!C14 -> 7851647 | E58: =Development!D14 -> 7851647 | F58: =Development!E14 -> 7851647 | G58: =Development!F14 -> 7851647
C59: =Financing!B7 -> 700000 | D59: =Financing!C7 -> 700000 | E59: =Financing!D7 -> 700000 | F59: =Financing!E7 -> 700000 | G59: =Financing!F7 -> 700000
C60: =Financing!B13 -> 1041400 | D60: =Financing!C13 -> 1094400 | E60: =Financing!D13 -> 1234400 | F60: =Financing!E13 -> 1514400 | G60: =Financing!F13 -> 2339400
C61: =SUM(C54:C60) -> 27375747 | D61: =SUM(D54:D60) -> 32329547 | E61: =SUM(E54:E60) -> 41994047 | F61: =SUM(F54:F60) -> 64218047 | G61: =SUM(G54:G60) -> 118425047
C62: =C63-C61 -> 74036253 | D62: =D63-D61 -> 136690453 | E62: =E63-E61 -> 296045953 | F62: =F63-F61 -> 611861953 | G62: =G63-G61 -> 1571774953
...

Sheet Revenue
A1: Revenue Model — Assumptions & Derivation
A3: Revenue Stream | B3: Rate | C3: Adoption | D3: Basis | E3: Annual/Meter (N$)
A4: Meter Hardware Sale | B4: N$5,500/yr | C4: 100% | D4: Annual recurring | E4: 5500
A5: Installation Fee | B5: N$700 one-time | C5: 100% | D5: One-time | E5: 700
A6: Maintenance | B6: N$300/yr | C6: 100% | D6: Annual | E6: 300
A7: Wi-Fi Subscription | B7: N$25/mo | C7: 30% | D7: 30% x 25 x 12 | E7: 90
A8: SMS Notifications | B8: N$2.50/SMS | C8: 50% | D8: 50% x 2 x 2.50 x 12 | E8: 30
A9: Mobile App | B9: N$65/mo | C9: 80% | D9: 80% x 65 x 12 | E9: 624
A10: Real Estate Mgmt | B10: N$3,200/blk/mo | C10: 1/500m | D10: (m/500) x 3200 x 12 / m | E10: 76.8
A11: Annual Recurring per Meter | E11: =E4+E6+E7+E8+E9+E10 -> 6620.8
A12: Year 1 Total per Meter (incl Install) | E12: =E11+E5 -> 7320.8
A14: Revenue by Year & Scenario
A16: Year | B16: 3,000 Meters | C16: 5,000 Meters | D16: 10,000 Meters | E16: 20,000 Meters | F16: 50,000 Meters
A17: Year 2 | B17: 19862400 | C17: 33104000 | D17: 66208000 | E17: 132416000 | F17: 331040000
A18: Year 3 | B18: 19862400 | C18: 33104000 | D18: 66208000 | E18: 132416000 | F18: 331040000
A19: Year 4 | B19: 19862400 | C19: 33104000 | D19: 66208000 | E19: 132416000 | F19: 331040000
A20: Year 5 | B20: 19862400 | C20: 33104000 | D20: 66208000 | E20: 132416000 | F20: 331040000
A22: 5-Year Total | B22: =SUM(B17:B21) -> 79449600 | C22: =SUM(C17:C21) -> 132416000 | D22: =SUM(D17:D21) -> 264832000 | E22: =SUM(E17:E21) -> 529664000 | F22: =SUM(F17:F21) -> 1324160000
A24: 5-Year Revenue Breakdown by Stream
A26: Revenue Stream | B26: 3,000 Meters | C26: 5,000 Meters | D26: 10,000 Meters | E26: 20,000 Meters | F26: 50,000 Meters
A27: Hardware Sales (N$5,500/yr x 5) | B27: 82500000 | C27: 137500000 | D27: 275000000 | E27: 550000000 | F27: 1375000000
A28: Installation Fees (N$700 one-time) | B28: 2100000 | C28: 3500000 | D28: 7000000 | E28: 14000000 | F28: 35000000
A29: Maintenance (N$300/yr x 5) | B29: 4500000 | C29: 7500000 | D29: 15000000 | E29: 30000000 | F29: 75000000
A30: Wi-Fi (N$90/yr x 5) | B30: 1350000 | C30: 2250000 | D30: 4500000 | E30: 9000000 | F30: 22500000
A31: SMS (N$30/yr x 5) | B31: 450000 | C31: 750000 | D31: 1500000 | E31: 3000000 | F31: 7500000
A32: Mobile App (N$624/yr x 5) | B32: 9360000 | C32: 15600000 | D32: 31200000 | E32: 62400000 | F32: 156000000
A33: Real Estate (N$76.80/yr x 5) | B33: 1152000 | C33: 1920000 | D33: 3840000 | E33: 7680000 | F33: 19200000
A34: Total 5-Year Revenue | B34: =SUM(B27:B33) -> 101412000 | C34: =SUM(C27:C33) -> 169020000 | D34: =SUM(D27:D33) -> 338040000 | E34: =SUM(E27:E33) -> 676080000 | F34: =SUM(F27:F33) -> 1690200000

Sheet Manufacturing
A1: Manufacturing Costs — Derivation
A3: VOLUME DISCOUNT STRUCTURE
A5: Volume Tier | B5: Discount | C5: Cost/Meter (N$) | D5: Calculation Basis
A6: Base (0-9,999) | B6: 0% | C6: 2000 | D6: N$2,000 per meter
A7: 10,000 - 19,999 | B7: 15% | C7: 1700 | D7: 15% reduction
A8: 20,000 - 49,999 | B8: 30% | C8: 1400 | D8: 30% reduction
A9: 50,000+ | B9: ~27% | C9: 1462 | D9: Adjusted to N$1,462
A11: MANUFACTURING COST BY SCENARIO
A13: Cost Item | B13: 3,000 Meters | C13: 5,000 Meters | D13: 10,000 Meters | E13: 20,000 Meters | F13: 50,000 Meters
A14: Meter Hardware (Volume x Unit Cost) | B14: 6000000 | C14: 10000000 | D14: 17000000 | E14: 34000000 | F14: 73100000
A15: Spare Parts (2% x N$4,495/meter) | B15: 269700 | C15: 449500 | D15: 899000 | E15: 1798000 | F15: 4495000
A16: TOTAL MANUFACTURING | B16: =SUM(B14:B15) -> 6269700 | C16: =SUM(C14:C15) -> 10449500 | D16: =SUM(D14:D15) -> 17899000 | E16: =SUM(E14:E15) -> 35798000 | F16: =SUM(F14:F15) -> 77595000
A18: UNIT COST SUMMARY
A19: Metric | B19: 3,000 Meters | C19: 5,000 Meters | D19: 10,000 Meters | E19: 20,000 Meters | F19: 50,000 Meters
A20: Meters Deployed | B20: 3000 | C20: 5000 | D20: 10000 | E20: 20000 | F20: 50000
A21: Cost per Meter (N$) | B21: 2000 | C21: 2000 | D21: 1700 | E21: 1700 | F21: 1462
A22: Discount Applied | B22: 0% | C22: 0% | D22: 15% | E22: 15% | F22: 27%

Sheet Personnel
A1: Personnel — Detailed Staffing Plan
A2: Headcount by position per deployment scenario
A4: Position | B4: 3,000 Meters | C4: 5,000 Meters | D4: 10,000 Meters | E4: 20,000 Meters | F4: 50,000 Meters | H4: Position | I4: Monthly (N$) | J4: Annual (N$)
A5: LEADERSHIP & MANAGEMENT
A6: CEO | B6: 1 | C6: 1 | D6: 1 | E6: 1 | F6: 1 | H6: CEO | I6: 35000 | J6: =I6*12 -> 420000
A7: COO | B7: 0 | C7: 0 | D7: 1 | E7: 1 | F7: 1 | H7: COO | I7: 28000 | J7: =I7*12 -> 336000
A8: CFO | B8: 0 | C8: 1 | D8: 1 | E8: 1 | F8: 1 | H8: CFO | I8: 28000 | J8: =I8*12 -> 336000
A9: CTO | B9: 0 | C9: 1 | D9: 1 | E9: 1 | F9: 1 | H9: CTO | I9: 30000 | J9: =I9*12 -> 360000
A10: Head of Business Dev | B10: 0 | C10: 0 | D10: 1 | E10: 1 | F10: 1 | H10: Head of Business Dev | I10: 25000 | J10: =I10*12 -> 300000
A11: Head of HR | B11: 0 | C11: 0 | D11: 0 | E11: 1 | F11: 1 | H11: Head of HR | I11: 22000 | J11: =I11*12 -> 264000
A12: Legal & Compliance | B12: 0 | C12: 0 | D12: 0 | E12: 1 | F12: 1 | H12: Legal & Compliance | I12: 22000 | J12: =I12*12 -> 264000
A13: OPERATIONS & FIELD
A14: Operations Manager | B14: 0 | C14: 1 | D14: 1 | E14: 1 | F14: 1 | H14: Operations Manager | I14: 20000 | J14: =I14*12 -> 240000
A15: Field Support Techs | B15: 2 | C15: 3 | D15: 4 | E15: 5 | F15: 8 | H15: Field Support Techs | I15: 9000 | J15: =I15*12 -> 108000
A16: Installation Team Lead | B16: 0 | C16: 1 | D16: 1 | E16: 2 | F16: 3 | H16: Installation Team Lead | I16: 11000 | J16: =I16*12 -> 132000
A17: Logistics Coordinator | B17: 0 | C17: 0 | D17: 1 | E17: 1 | F17: 2 | H17: Logistics Coordinator | I17: 8000 | J17: =I17*12 -> 96000
A18: ENGINEERING & QA
A19: Engineering Manager | B19: 0 | C19: 0 | D19: 1 | E19: 1 | F19: 1 | H19: Engineering Manager | I19: 22000 | J19: =I19*12 -> 264000
A20: QA Engineers | B20: 1 | C20: 1 | D20: 1 | E20: 3 | F20: 5 | H20: QA Engineers | I20: 12000 | J20: =I20*12 -> 144000
A21: Firmware/Software Eng | B21: 0 | C21: 1 | D21: 2 | E21: 3 | F21: 5 | H21: Firmware/Software Eng | I21: 15000 | J21: =I21*12 -> 180000
A22: Hardware Engineers | B22: 0 | C22: 0 | D22: 1 | E22: 2 | F22: 3 | H22: Hardware Engineers | I22: 15000 | J22: =I22*12 -> 180000
A23: CUSTOMER SUCCESS
A24: Customer Support Mgr | B24: 0 | C24: 0 | D24: 1 | E24: 1 | F24: 1 | H24: Customer Support Mgr | I24: 18000 | J24: =I24*12 -> 216000
A25: Customer Support Agents | B25: 1 | C25: 2 | D25: 2 | E25: 4 | F25: 8 | H25: Customer Support Agents | I25: 7200 | J25: =I25*12 -> 86400
A26: Technical Support | B26: 0 | C26: 0 | D26: 1 | E26: 2 | F26: 3 | H26: Technical Support | I26: 9000 | J26: =I26*12 -> 108000
A27: SALES & MARKETING
A28: Sales Manager | B28: 0 | C28: 0 | D28: 1 | E28: 1 | F28: 1 | H28: Sales Manager | I28: 20000 | J28: =I28*12 -> 240000
A29: Sales Representatives | B29: 0 | C29: 1 | D29: 2 | E29: 3 | F29: 5 | H29: Sales Representatives | I29: 10000 | J29: =I29*12 -> 120000
A30: Marketing Coordinator | B30: 0 | C30: 0 | D30: 1 | E30: 1 | F30: 2 | H30: Marketing Coordinator | I30: 9000 | J30: =I30*12 -> 108000
A31: FINANCE & ADMIN
A32: Finance Manager | B32: 0 | C32: 0 | D32: 1 | E32: 1 | F32: 1 | H32: Finance Manager | I32: 20000 | J32: =I32*12 -> 240000
A33: Accountant | B33: 0 | C33: 1 | D33: 1 | E33: 2 | F33: 3 | H33: Accountant | I33: 11000 | J33: =I33*12 -> 132000
A34: Admin Assistant | B34: 0 | C34: 0 | D34: 1 | E34: 2 | F34: 3 | H34: Admin Assistant | I34: 7000 | J34: =I34*12 -> 84000
A35: TOTAL HEADCOUNT | B35: =SUMPRODUCT((B5:B34)*(B5:B34<>0)*1) -> 5 | C35: =SUMPRODUCT((C5:C34)*(C5:C34<>0)*1) -> 14 | D35: =SUMPRODUCT((D5:D34)*(D5:D34<>0)*1) -> 28 | E35: =SUMPRODUCT((E5:E34)*(E5:E34<>0)*1) -> 42 | F35: =SUMPRODUCT((F5:F34)*(F5:F34<>0)*1) -> 62
A37: ANNUAL PERSONNEL COST BY SCENARIO
A38: Position | B38: Annual Salary | C38: 3,000 Meters | D38: 5,000 Meters | E38: 10,000 Meters | F38: 20,000 Meters | G38: 50,000 Meters
A39: LEADERSHIP & MANAGEMENT
A40: CEO | B40: 420000 | C40: 420000 | D40: 420000 | E40: 420000 | F40: 420000 | G40: 420000
A41: COO | B41: 336000 | C41: 0 | D41: 0 | E41: 336000 | F41: 336000 | G41: 336000
A42: CFO | B42: 336000 | C42: 0 | D42: 336000 | E42: 336000 | F42: 336000 | G42: 336000
...

Sheet Operating Costs
A1: Operating Costs — 5-Year Total
A2: Annual recurring costs x 5 years
A4: Cost Item | B4: 3,000 Meters | C4: 5,000 Meters | D4: 10,000 Meters | E4: 20,000 Meters | F4: 50,000 Meters
A5: Personnel (N$748,800/yr x 5) | B5: 3744000 | C5: 3744000 | D5: 3744000 | E5: 3744000 | F5: 3744000
A6: Data Storage (N$48/meter/yr x 5) | B6: 720000 | C6: 1200000 | D6: 2400000 | E6: 4800000 | F6: 12000000
A7: Vehicle Maintenance | B7: 300000 | C7: 300000 | D7: 450000 | E7: 750000 | F7: 1500000
A8: Field Equipment Upkeep | B8: 100000 | C8: 150000 | D8: 200000 | E8: 300000 | F8: 600000
A9: Office & Utilities (N$240,000/yr x 5) | B9: 1200000 | C9: 1200000 | D9: 1200000 | E9: 1200000 | F9: 1200000
A10: Software & Tools (N$120,000/yr x 5) | B10: 600000 | C10: 600000 | D10: 600000 | E10: 600000 | F10: 600000
A11: Marketing & Branding (N$200,000/yr x 5) | B11: 1000000 | C11: 1000000 | D11: 1000000 | E11: 1000000 | F11: 1000000
A12: Regulatory Compliance (N$100,000/yr x 5) | B12: 500000 | C12: 500000 | D12: 500000 | E12: 500000 | F12: 500000
A13: Insurance & Risk (N$150,000/yr x 5) | B13: 750000 | C13: 750000 | D13: 750000 | E13: 750000 | F13: 750000
A14: TOTAL OPERATING (5-Year) | B14: =SUM(B5:B13) -> 8914000 | C14: =SUM(C5:C13) -> 9444000 | D14: =SUM(D5:D13) -> 10844000 | E14: =SUM(E5:E13) -> 13644000 | F14: =SUM(F5:F13) -> 21894000

Sheet Implementation
A1: Implementation Costs — One-Time
A2: Deployment and setup costs (Year 1 only)
A4: Cost Item | B4: 3,000 Meters | C4: 5,000 Meters | D4: 10,000 Meters | E4: 20,000 Meters | F4: 50,000 Meters
A5: Project Management | B5: 500000 | C5: 500000 | D5: 500000 | E5: 500000 | F5: 500000
A6: Site Surveys & Assessment | B6: 300000 | C6: 300000 | D6: 300000 | E6: 300000 | F6: 300000
A7: Onboarding & Training | B7: 250000 | C7: 250000 | D7: 250000 | E7: 250000 | F7: 250000
A8: System Integration | B8: 450000 | C8: 450000 | D8: 450000 | E8: 450000 | F8: 450000
A9: TOTAL IMPLEMENTATION | B9: =SUM(B5:B8) -> 1500000 | C9: =SUM(C5:C8) -> 1500000 | D9: =SUM(D5:D8) -> 1500000 | E9: =SUM(E5:E8) -> 1500000 | F9: =SUM(F5:F8) -> 1500000

Sheet Equipment
A1: Equipment Investment — One-Time
A2: Capital equipment purchases (Year 1 only)
A4: Cost Item | B4: 3,000 Meters | C4: 5,000 Meters | D4: 10,000 Meters | E4: 20,000 Meters | F4: 50,000 Meters
A5: Service Vehicles (N$250,000 each) | B5: 500000 | C5: 500000 | D5: 750000 | E5: 1250000 | F5: 2500000
A6: Test Equipment Kits (N$85,000 each) | B6: 170000 | C6: 255000 | D6: 340000 | E6: 510000 | F6: 1020000
A7: Workstations (N$15,000 each) | B7: 45000 | C7: 75000 | D7: 105000 | E7: 180000 | F7: 375000
A8: Network Monitoring (N$120,000 each) | B8: 120000 | C8: 120000 | D8: 240000 | E8: 360000 | F8: 600000
A9: Office Furniture | B9: 119000 | C9: 165000 | D9: 280000 | E9: 510000 | F9: 1200000
A10: Server/Cloud Infrastructure | B10: 145000 | C10: 175000 | D10: 250000 | E10: 400000 | F10: 850000
A11: TOTAL EQUIPMENT | B11: =SUM(B5:B10) -> 1099000 | C11: =SUM(C5:C10) -> 1290000 | D11: =SUM(D5:D10) -> 1965000 | E11: =SUM(E5:E10) -> 3210000 | F11: =SUM(F5:F10) -> 6545000
A13: EQUIPMENT QUANTITIES
A14: Item | B14: 3,000 Meters | C14: 5,000 Meters | D14: 10,000 Meters | E14: 20,000 Meters | F14: 50,000 Meters
A15: Service Vehicles | B15: 2 | C15: 2 | D15: 3 | E15: 5 | F15: 10
A16: Test Equipment Kits | B16: 2 | C16: 3 | D16: 4 | E16: 6 | F16: 12
A17: Workstations | B17: 3 | C17: 5 | D17: 7 | E17: 12 | F17: 25
A18: Network Monitoring Tools | B18: 1 | C18: 1 | D18: 2 | E18: 3 | F18: 5

Sheet Development
A1: Development Costs — Pre-Launch
A2: R&D and product development (one-time investment)
A4: Cost Item | B4: 3,000 Meters | C4: 5,000 Meters | D4: 10,000 Meters | E4: 20,000 Meters | F4: 50,000 Meters
A5: Electronics Manufacturing Dev | B5: 312000 | C5: 312000 | D5: 312000 | E5: 312000 | F5: 312000
A6: Software R&D | B6: 777747 | C6: 777747 | D6: 777747 | E6: 777747 | F6: 777747
A7: Mobile App Development | B7: 300000 | C7: 300000 | D7: 300000 | E7: 300000 | F7: 300000
A8: Firmware Development | B8: 2160000 | C8: 2160000 | D8: 2160000 | E8: 2160000 | F8: 2160000
A9: Enclosure Manufacturing | B9: 1403850 | C9: 1403850 | D9: 1403850 | E9: 1403850 | F9: 1403850
A10: Marketing/Branding Launch | B10: 325000 | C10: 325000 | D10: 325000 | E10: 325000 | F10: 325000
A11: Regulatory & Legal | B11: 1060000 | C11: 1060000 | D11: 1060000 | E11: 1060000 | F11: 1060000
A12: Office/Logistics Setup | B12: 897400 | C12: 897400 | D12: 897400 | E12: 897400 | F12: 897400
A13: Development Contingency (5%) | B13: 615650 | C13: 615650 | D13: 615650 | E13: 615650 | F13: 615650
A14: TOTAL DEVELOPMENT | B14: =SUM(B5:B13) -> 7851647 | C14: =SUM(C5:C13) -> 7851647 | D14: =SUM(D5:D13) -> 7851647 | E14: =SUM(E5:E13) -> 7851647 | F14: =SUM(F5:F13) -> 7851647

Sheet Financing
A1: Financing & Contingency
A3: FINANCING COSTS
A4: Cost Item | B4: 3,000 Meters | C4: 5,000 Meters | D4: 10,000 Meters | E4: 20,000 Meters | F4: 50,000 Meters
A5: Interest on Working Capital | B5: 500000 | C5: 500000 | D5: 500000 | E5: 500000 | F5: 500000
A6: Bank Fees & Charges | B6: 200000 | C6: 200000 | D6: 200000 | E6: 200000 | F6: 200000
A7: TOTAL FINANCING | B7: =SUM(B5:B6) -> 700000 | C7: =SUM(C5:C6) -> 700000 | D7: =SUM(D5:D6) -> 700000 | E7: =SUM(E5:E6) -> 700000 | F7: =SUM(F5:F6) -> 700000
A9: CONTINGENCY RESERVES
A10: Cost Item | B10: 3,000 Meters | C10: 5,000 Meters | D10: 10,000 Meters | E10: 20,000 Meters | F10: 50,000 Meters
A11: Operating Contingency (10% of 5Y Operating) | B11: ='Operating Costs'!B14*0.1 -> 891400 | C11: ='Operating Costs'!C14*0.1 -> 944400 | D11: ='Operating Costs'!D14*0.1 -> 1084400 | E11: ='Operating Costs'!E14*0.1 -> 1364400 | F11: ='Operating Costs'!F14*0.1 -> 2189400
A12: Implementation Contingency (10%) | B12: =Implementation!B9*0.1 -> 150000 | C12: =Implementation!C9*0.1 -> 150000 | D12: =Implementation!D9*0.1 -> 150000 | E12: =Implementation!E9*0.1 -> 150000 | F12: =Implementation!F9*0.1 -> 150000
A13: TOTAL CONTINGENCY | B13: =SUM(B11:B12) -> 1041400 | C13: =SUM(C11:C12) -> 1094400 | D13: =SUM(D11:D12) -> 1234400 | E13: =SUM(E11:E12) -> 1514400 | F13: =SUM(F11:F12) -> 2339400

Sheet Profitability
A1: Profitability Analysis — All Scenarios
A3: YEAR 1 ANALYSIS
A5: Metric | B5: 3,000 Meters | C5: 5,000 Meters | D5: 10,000 Meters | E5: 20,000 Meters | F5: 50,000 Meters
A6: Year 1 Revenue | B6: 21962400 | C6: 36604000 | D6: 73208000 | E6: 146416000 | F6: 366040000
A7: YEAR 1 COSTS:
A8: Manufacturing (one-time) | B8: =Manufacturing!B16 -> 6269700 | C8: =Manufacturing!C16 -> 10449500 | D8: =Manufacturing!D16 -> 17899000 | E8: =Manufacturing!E16 -> 35798000 | F8: =Manufacturing!F16 -> 77595000
A9: Operating (1 year) | B9: ='Operating Costs'!B14*0.2 -> 1782800 | C9: ='Operating Costs'!C14*0.2 -> 1888800 | D9: ='Operating Costs'!D14*0.2 -> 2168800 | E9: ='Operating Costs'!E14*0.2 -> 2728800 | F9: ='Operating Costs'!F14*0.2 -> 4378800
A10: Implementation (one-time) | B10: =Implementation!B9 -> 1500000 | C10: =Implementation!C9 -> 1500000 | D10: =Implementation!D9 -> 1500000 | E10: =Implementation!E9 -> 1500000 | F10: =Implementation!F9 -> 1500000
A11: Equipment (one-time) | B11: =Equipment!B11 -> 1099000 | C11: =Equipment!C11 -> 1290000 | D11: =Equipment!D11 -> 1965000 | E11: =Equipment!E11 -> 3210000 | F11: =Equipment!F11 -> 6545000
A12: Development (one-time) | B12: =Development!B14 -> 7851647 | C12: =Development!C14 -> 7851647 | D12: =Development!D14 -> 7851647 | E12: =Development!E14 -> 7851647 | F12: =Development!F14 -> 7851647
A13: Financing | B13: =Financing!B7 -> 700000 | C13: =Financing!C7 -> 700000 | D13: =Financing!D7 -> 700000 | E13: =Financing!E7 -> 700000 | F13: =Financing!F7 -> 700000
A14: Contingency (1 year) | B14: =Financing!B13*0.2 -> 208280 | C14: =Financing!C13*0.2 -> 218880 | D14: =Financing!D13*0.2 -> 246880 | E14: =Financing!E13*0.2 -> 302880 | F14: =Financing!F13*0.2 -> 467880
A15: Total Year 1 Costs | B15: =SUM(B8:B14) -> 19411427 | C15: =SUM(C8:C14) -> 23898827 | D15: =SUM(D8:D14) -> 32331327 | E15: =SUM(E8:E14) -> 52091327 | F15: =SUM(F8:F14) -> 99038327
A16: Year 1 Net Profit | B16: =B6-B15 -> 2550973 | C16: =C6-C15 -> 12705173 | D16: =D6-D15 -> 40876673 | E16: =E6-E15 -> 94324673 | F16: =F6-F15 -> 267001673
A17: Year 1 Net Margin | B17: =IF(B6>0,B16/B6,0) -> 0.11615183 | C17: =IF(C6>0,C16/C6,0) -> 0.34709794 | D17: =IF(D6>0,D16/D6,0) -> 0.55836347 | E17: =IF(E6>0,E16/E6,0) -> 0.64422381 | F17: =IF(F6>0,F16/F6,0) -> 0.72943305
A19: 5-YEAR PROJECTIONS
A21: Metric | B21: 3,000 Meters | C21: 5,000 Meters | D21: 10,000 Meters | E21: 20,000 Meters | F21: 50,000 Meters
A22: 5-Year Total Revenue | B22: =Revenue!B34 -> 101412000 | C22: =Revenue!C34 -> 169020000 | D22: =Revenue!D34 -> 338040000 | E22: =Revenue!E34 -> 676080000 | F22: =Revenue!F34 -> 1690200000
A23: 5-Year Total Costs | B23: =Manufacturing!B16+'Operating Costs'!B14+Implementation!B9+Equipment!B11+Development!B14+Financing!B7+Financing!B13 -> 27375747 | C23: =Manufacturing!C16+'Operating Costs'!C14+Implementation!C9+Equipment!C11+Development!C14+Financing!C7+Financing!C13 -> 32329547 | D23: =Manufacturing!D16+'Operating Costs'!D14+Implementation!D9+Equipment!D11+Development!D14+Financing!D7+Financing!D13 -> 41994047 | E23: =Manufacturing!E16+'Operating Costs'!E14+Implementation!E9+Equipment!E11+Development!E14+Financing!E7+Financing!E13 -> 64218047 | F23: =Manufacturing!F16+'Operating Costs'!F14+Implementation!F9+Equipment!F11+Development!F14+Financing!F7+Financing!F13 -> 118425047
A24: 5-Year Net Profit | B24: =B22-B23 -> 74036253 | C24: =C22-C23 -> 136690453 | D24: =D22-D23 -> 296045953 | E24: =E22-E23 -> 611861953 | F24: =F22-F23 -> 1571774953
A25: 5-Year ROI % | B25: =IF(B23>0,B24/B23,0) -> 2.7044469 | C25: =IF(C23>0,C24/C23,0) -> 4.2280349 | D25: =IF(D23>0,D24/D23,0) -> 7.0497124 | E25: =IF(E23>0,E24/E23,0) -> 9.5278817 | F25: =IF(F23>0,F24/F23,0) -> 13.272319
A26: 5-Year Net Margin % | B26: =IF(B22>0,B24/B22,0) -> 0.73005417 | C26: =IF(C22>0,C24/C22,0) -> 0.80872354 | D26: =IF(D22>0,D24/D22,0) -> 0.87577196 | E26: =IF(E22>0,E24/E22,0) -> 0.90501413 | F26: =IF(F22>0,F24/F22,0) -> 0.9299343
A27: Payback Period (months) | B27: 7.6 | C27: 7.2 | D27: 4.2 | E27: 3.9 | F27: 3.5
A28: DCF / Net Present Value | B28: 65500000 | C28: 119300000 | D28: 259647182 | E28: 538200000 | F28: 1390000000
A30: 5-YEAR COST BREAKDOWN
A32: Cost Category | B32: 3,000 Meters | C32: 5,000 Meters | D32: 10,000 Meters | E32: 20,000 Meters | F32: 50,000 Meters
A33: Manufacturing | B33: =Manufacturing!B16 -> 6269700 | C33: =Manufacturing!C16 -> 10449500 | D33: =Manufacturing!D16 -> 17899000 | E33: =Manufacturing!E16 -> 35798000 | F33: =Manufacturing!F16 -> 77595000
A34: Operating Costs (5Y) | B34: ='Operating Costs'!B14 -> 8914000 | C34: ='Operating Costs'!C14 -> 9444000 | D34: ='Operating Costs'!D14 -> 10844000 | E34: ='Operating Costs'!E14 -> 13644000 | F34: ='Operating Costs'!F14 -> 21894000
A35: Implementation | B35: =Implementation!B9 -> 1500000 | C35: =Implementation!C9 -> 1500000 | D35: =Implementation!D9 -> 1500000 | E35: =Implementation!E9 -> 1500000 | F35: =Implementation!F9 -> 1500000
A36: Equipment | B36: =Equipment!B11 -> 1099000 | C36: =Equipment!C11 -> 1290000 | D36: =Equipment!D11 -> 1965000 | E36: =Equipment!E11 -> 3210000 | F36: =Equipment!F11 -> 6545000
A37: Development | B37: =Development!B14 -> 7851647 | C37: =Development!C14 -> 7851647 | D37: =Development!D14 -> 7851647 | E37: =Development!E14 -> 7851647 | F37: =Development!F14 -> 7851647
A38: Financing | B38: =Financing!B7 -> 700000 | C38: =Financing!C7 -> 700000 | D38: =Financing!D7 -> 700000 | E38: =Financing!E7 -> 700000 | F38: =Financing!F7 -> 700000
A39: Contingency | B39: =Financing!B13 -> 1041400 | C39: =Financing!C13 -> 1094400 | D39: =Financing!D13 -> 1234400 | E39: =Financing!E13 -> 1514400 | F39: =Financing!F13 -> 2339400
A40: TOTAL 5-YEAR COSTS | B40: =SUM(B33:B39) -> 27375747 | C40: =SUM(C33:C39) -> 32329547 | D40: =SUM(D33:D39) -> 41994047 | E40: =SUM(E33:E39) -> 64218047 | F40: =SUM(F33:F39) -> 118425047
