Workbook

Sheet Dashboard
B2: Input Parameters | E2: ="5-Year Financial Overview ("&$B$5&")" -> 5-Year Financial Overview (10,000 Meters)
B4: Meter Rollout:
B5: 10,000 Meters
B7: Hardware Price | C7: Per Unit
B8: 5500
B10: Installation Fee | C10: Per Unit
B11: 700
B13: Manufacturing Cost | C13: Per Unit
B14: =INDEX($C$54:$G$54,1,$C$52) -> 1700
B16: Personnel Cost | C16: / Year
B17: =INDEX($C$56:$G$56,1,$C$52) -> 5140800
L18: Profit Margins
B19: Infrastructure Cost | C19: / Year | M19: Gross Margin | O19: =D75 -> 0.75872151
B20: =INDEX($C$57:$G$57,1,$C$52) -> 840000 | M20: Oper. Margin | O20: =D76 -> 0.6738369
M21: Net Margin | O21: =D77 -> 0.62871782
B22: Service Revenue | C22: / Year
B23: =INDEX($C$53:$G$53,1,$C$52)*SUM(Revenue!$E$6:$E$10) -> 8458000 | L23: Payback Period
L24: =D78 -> 105
B25: Equipment | C25: One-Time
B26: =INDEX($C$58:$G$58,1,$C$52) -> 3179000 | L26: Days
B50: DATA AREA
C51: 3,000 Meters | D51: 5,000 Meters | E51: 10,000 Meters | F51: 20,000 Meters | G51: 50,000 Meters
B52: Index | C52: =MATCH($B$5,$C$51:$G$51,0) -> 3
C53: 3000 | D53: 5000 | E53: 10000 | F53: 20000 | G53: 50000
C54: ='Manufacturing Cost'!C13 -> 2000 | D54: ='Manufacturing Cost'!C14 -> 2000 | E54: ='Manufacturing Cost'!C15 -> 1700 | F54: ='Manufacturing Cost'!C16 -> 1700 | G54: ='Manufacturing Cost'!C17 -> 1462
C55: ='Manufacturing Cost'!D13 -> 6000000 | D55: ='Manufacturing Cost'!D14 -> 10000000 | E55: ='Manufacturing Cost'!D15 -> 17000000 | F55: ='Manufacturing Cost'!D16 -> 34000000 | G55: ='Manufacturing Cost'!D17 -> 73100000
C56: ='Personnel Cost'!C91 -> 866400 | D56: ='Personnel Cost'!D91 -> 2560800 | E56: ='Personnel Cost'!E91 -> 5140800 | F56: ='Personnel Cost'!F91 -> 7173600 | G56: ='Personnel Cost'!G91 -> 9571200
C57: ='Infrastructure & Equipment'!C7 -> 240000 | D57: ='Infrastructure & Equipment'!D7 -> 420000 | E57: ='Infrastructure & Equipment'!E7 -> 840000 | F57: ='Infrastructure & Equipment'!F7 -> 1560000 | G57: ='Infrastructure & Equipment'!G7 -> 3480000
C58: ='Infrastructure & Equipment'!C19 -> 949700 | D58: ='Infrastructure & Equipment'!D19 -> 1739500 | E58: ='Infrastructure & Equipment'!E19 -> 3179000 | F58: ='Infrastructure & Equipment'!F19 -> 5038000 | G58: ='Infrastructure & Equipment'!G19 -> 10225000
D61: Year 1 | E61: Year 2 | F61: Year 3 | G61: Year 4 | H61: Year 5
C62: Revenue | D62: =INDEX($C$53:$G$53,1,$C$52)*Revenue!$E$11 -> 70458000 | E62: =INDEX($C$53:$G$53,1,$C$52)*SUM(Revenue!$E$6:$E$10) -> 8458000 | F62: =INDEX($C$53:$G$53,1,$C$52)*SUM(Revenue!$E$6:$E$10) -> 8458000 | G62: =INDEX($C$53:$G$53,1,$C$52)*SUM(Revenue!$E$6:$E$10) -> 8458000 | H62: =INDEX($C$53:$G$53,1,$C$52)*SUM(Revenue!$E$6:$E$10) -> 8458000
C63: EBITDA | D63: =D62-D65-D66 -> 47477200 | E63: =E62-E66 -> 2477200 | F63: =F62-F66 -> 2477200 | G63: =G62-G66 -> 2477200 | H63: =H62-H66 -> 2477200
C64: Net Profit | D64: =D63-D67 -> 44298200 | E64: =E63-E67 -> 2477200 | F64: =F63-F67 -> 2477200 | G64: =G63-G67 -> 2477200 | H64: =H63-H67 -> 2477200
C65: Mfg Cost | D65: =INDEX($C$55:$G$55,1,$C$52) -> 17000000 | E65: 0 | F65: 0 | G65: 0 | H65: 0
C66: Oper Cost | D66: =INDEX($C$56:$G$56,1,$C$52)+INDEX($C$57:$G$57,1,$C$52) -> 5980800 | E66: =$D$66 -> 5980800 | F66: =$D$66 -> 5980800 | G66: =$D$66 -> 5980800 | H66: =$D$66 -> 5980800
C67: Equipment | D67: =INDEX($C$58:$G$58,1,$C$52) -> 3179000 | E67: 0 | F67: 0 | G67: 0 | H67: 0
C68: Total Costs | D68: =D65+D66+D67 -> 26159800 | E68: =E65+E66+E67 -> 5980800 | F68: =F65+F66+F67 -> 5980800 | G68: =G65+G66+G67 -> 5980800 | H68: =H65+H66+H67 -> 5980800
C69: Cum Rev | D69: =D62 -> 70458000 | E69: =D69+E62 -> 78916000 | F69: =E69+F62 -> 87374000 | G69: =F69+G62 -> 95832000 | H69: =G69+H62 -> 104290000
C70: Cum Profit | D70: =D64 -> 44298200 | E70: =D70+E64 -> 46775400 | F70: =E70+F64 -> 49252600 | G70: =F70+G64 -> 51729800 | H70: =G70+H64 -> 54207000
D72: Net Profit | E72: Operating Costs | F72: Manufacturing | G72: Equipment
...

Sheet Personnel Cost
A1: Resource Type | B1: 3,000 Meters | C1: 5,000 Meters | D1: 10,000 Meters | E1: 20,000 Meters | F1: 50,000 Meters | H1: Position | I1: Monthly Salary (N$) | J1: Annual Salary (N$)
A2: LEADERSHIP & MANAGEMENT | H2: Chief Executive Officer (CEO) | I2: 35000 | J2: =I2*12 -> 420000
A3: Chief Executive Officer (CEO) | B3: 1 | C3: 1 | D3: 1 | E3: 1 | F3: 1 | H3: Chief Operations Officer (COO) | I3: 28000 | J3: =I3*12 -> 336000
A4: Chief Operations Officer (COO) | B4: 0 | C4: 0 | D4: 1 | E4: 1 | F4: 1 | H4: Chief Financial Officer (CFO) | I4: 28000 | J4: =I4*12 -> 336000
A5: Chief Financial Officer (CFO) | B5: 0 | C5: 1 | D5: 1 | E5: 1 | F5: 1 | H5: Chief Technology Officer (CTO) | I5: 30000 | J5: =I5*12 -> 360000
A6: Chief Technology Officer (CTO) | B6: 0 | C6: 1 | D6: 1 | E6: 1 | F6: 1 | H6: Head of Business Development | I6: 25000 | J6: =I6*12 -> 300000
A7: Head of Business Development | B7: 0 | C7: 0 | D7: 1 | E7: 1 | F7: 1 | H7: Head of Human Resources | I7: 22000 | J7: =I7*12 -> 264000
A8: Head of Human Resources | B8: 0 | C8: 0 | D8: 0 | E8: 1 | F8: 1 | H8: Legal & Compliance Officer | I8: 22000 | J8: =I8*12 -> 264000
A9: Legal & Compliance Officer | B9: 0 | C9: 0 | D9: 0 | E9: 1 | F9: 1 | H9: Operations Manager | I9: 20000 | J9: =I9*12 -> 240000
A10: Subtotal – LEADERSHIP | B10: =SUM(B3:B9) -> 1 | C10: =SUM(C3:C9) -> 3 | D10: =SUM(D3:D9) -> 5 | E10: =SUM(E3:E9) -> 7 | F10: =SUM(F3:F9) -> 7 | H10: Field Support Technicians | I10: 9000 | J10: =I10*12 -> 108000
H11: Installation Team Lead | I11: 11000 | J11: =I11*12 -> 132000
A12: OPERATIONS & FIELD SERVICES | H12: Logistics Coordinator | I12: 8000 | J12: =I12*12 -> 96000
A13: Operations Manager | B13: 0 | C13: 1 | D13: 1 | E13: 1 | F13: 1 | H13: Engineering Manager | I13: 22000 | J13: =I13*12 -> 264000
A14: Field Support Technicians | B14: 2 | C14: 3 | D14: 4 | E14: 5 | F14: 8 | H14: Quality Assurance Engineers | I14: 12000 | J14: =I14*12 -> 144000
A15: Installation Team Lead | B15: 0 | C15: 1 | D15: 1 | E15: 2 | F15: 3 | H15: Firmware/Software Engineers | I15: 15000 | J15: =I15*12 -> 180000
A16: Logistics Coordinator | B16: 0 | C16: 0 | D16: 1 | E16: 1 | F16: 2 | H16: Hardware Engineers | I16: 15000 | J16: =I16*12 -> 180000
A17: Subtotal – OPERATIONS | B17: =SUM(B13:B16) -> 2 | C17: =SUM(C13:C16) -> 5 | D17: =SUM(D13:D16) -> 7 | E17: =SUM(E13:E16) -> 9 | F17: =SUM(F13:F16) -> 14 | H17: Customer Support Manager | I17: 18000 | J17: =I17*12 -> 216000
H18: Customer Support Agents | I18: 7200 | J18: =I18*12 -> 86400
A19: ENGINEERING & QUALITY | H19: Technical Support Specialists | I19: 9000 | J19: =I19*12 -> 108000
A20: Engineering Manager | B20: 0 | C20: 0 | D20: 1 | E20: 1 | F20: 1 | H20: Sales Manager | I20: 20000 | J20: =I20*12 -> 240000
A21: Quality Assurance Engineers | B21: 1 | C21: 1 | D21: 1 | E21: 3 | F21: 5 | H21: Sales Representatives | I21: 10000 | J21: =I21*12 -> 120000
A22: Firmware/Software Engineers | B22: 0 | C22: 1 | D22: 2 | E22: 3 | F22: 5 | H22: Marketing Coordinator | I22: 9000 | J22: =I22*12 -> 108000
A23: Hardware Engineers | B23: 0 | C23: 0 | D23: 1 | E23: 2 | F23: 3 | H23: Finance Manager | I23: 20000 | J23: =I23*12 -> 240000
A24: Subtotal – ENGINEERING | B24: =SUM(B20:B23) -> 1 | C24: =SUM(C20:C23) -> 2 | D24: =SUM(D20:D23) -> 5 | E24: =SUM(E20:E23) -> 9 | F24: =SUM(F20:F23) -> 14 | H24: Accountant | I24: 11000 | J24: =I24*12 -> 132000
H25: Administrative Assistant | I25: 7000 | J25: =I25*12 -> 84000
A26: CUSTOMER SUCCESS & SUPPORT
A27: Customer Support Manager | B27: 0 | C27: 0 | D27: 1 | E27: 1 | F27: 1
A28: Customer Support Agents | B28: 1 | C28: 2 | D28: 2 | E28: 4 | F28: 8
A29: Technical Support Specialists | B29: 0 | C29: 0 | D29: 1 | E29: 2 | F29: 3
A30: Subtotal – CUSTOMER | B30: =SUM(B27:B29) -> 1 | C30: =SUM(C27:C29) -> 2 | D30: =SUM(D27:D29) -> 4 | E30: =SUM(E27:E29) -> 7 | F30: =SUM(F27:F29) -> 12
A32: SALES & MARKETING
A33: Sales Manager | B33: 0 | C33: 0 | D33: 1 | E33: 1 | F33: 1
A34: Sales Representatives | B34: 0 | C34: 1 | D34: 2 | E34: 3 | F34: 5
A35: Marketing Coordinator | B35: 0 | C35: 0 | D35: 1 | E35: 1 | F35: 2
A36: Subtotal – SALES | B36: =SUM(B33:B35) -> 0 | C36: =SUM(C33:C35) -> 1 | D36: =SUM(D33:D35) -> 4 | E36: =SUM(E33:E35) -> 5 | F36: =SUM(F33:F35) -> 8
A38: FINANCE & ADMINISTRATION
A39: Finance Manager | B39: 0 | C39: 0 | D39: 1 | E39: 1 | F39: 1
A40: Accountant | B40: 0 | C40: 1 | D40: 1 | E40: 2 | F40: 3
A41: Administrative Assistant | B41: 0 | C41: 0 | D41: 1 | E41: 2 | F41: 3
A42: Subtotal – FINANCE | B42: =SUM(B39:B41) -> 0 | C42: =SUM(C39:C41) -> 1 | D42: =SUM(D39:D41) -> 3 | E42: =SUM(E39:E41) -> 5 | F42: =SUM(F39:F41) -> 7
...

Sheet Infrastructure & Equipment
A1: Infrastructure Costs (Annual)
A3: Cost Category | B3: Unit Cost | C3: 3,000 Meters | D3: 5,000 Meters | E3: 10,000 Meters | F3: 20,000 Meters | G3: 50,000 Meters
A4: Data Storage & Transmission | B4: N$48/meter | C4: 144000 | D4: 240000 | E4: 480000 | F4: 960000 | G4: 2400000
A5: Office Space Rental | B5: N$200/sq m | C5: 60000 | D5: 120000 | E5: 240000 | F5: 360000 | G5: 600000
A6: Utilities & Connectivity | B6: Lump sum | C6: 36000 | D6: 60000 | E6: 120000 | F6: 240000 | G6: 480000
A7: Annual Infrastructure Total | C7: =SUM(C4:C6) -> 240000 | D7: =SUM(D4:D6) -> 420000 | E7: =SUM(E4:E6) -> 840000 | F7: =SUM(F4:F6) -> 1560000 | G7: =SUM(G4:G6) -> 3480000
A9: Equipment Costs (One-Time Investment)
A11: Equipment Type | B11: Unit Cost | C11: 3,000 Meters | D11: 5,000 Meters | E11: 10,000 Meters | F11: 20,000 Meters | G11: 50,000 Meters
A12: Service Vehicles | B12: N$250,000 | C12: 250000 | D12: 500000 | E12: 750000 | F12: 750000 | G12: 1250000
A13: Field Test Equipment Kits | B13: N$85,000 | C13: 85000 | D13: 170000 | E13: 340000 | F13: 680000 | G13: 1530000
A14: Spare Parts Inventory | B14: N$4,495 × 2% | C14: 269700 | D14: 449500 | E14: 899000 | F14: 1798000 | G14: 4495000
A15: Workstations | B15: N$15,000 | C15: 75000 | D15: 210000 | E15: 420000 | F15: 630000 | G15: 930000
A16: Network Monitoring Tools | B16: N$120,000 | C16: 120000 | D16: 120000 | E16: 240000 | F16: 360000 | G16: 600000
A17: Office Equipment & Furniture | B17: Per employee | C17: 50000 | D17: 140000 | E17: 280000 | F17: 420000 | G17: 620000
A18: Server/Cloud Infrastructure | B18: Lump sum | C18: 100000 | D18: 150000 | E18: 250000 | F18: 400000 | G18: 800000
A19: Total Equipment Investment | C19: =SUM(C12:C18) -> 949700 | D19: =SUM(D12:D18) -> 1739500 | E19: =SUM(E12:E18) -> 3179000 | F19: =SUM(F12:F18) -> 5038000 | G19: =SUM(G12:G18) -> 10225000

Sheet Manufacturing Cost
A1: Volume Discount Structure
A3: Volume Tier | B3: Discount | C3: Cost per Meter (N$) | D3: Calculation Basis
A4: Base (0-9,999 meters) | B4: 0 | C4: 2000 | D4: N$2,000 per meter
A5: 10,000-19,999 meters | B5: 0.15 | C5: 1700 | D5: 15% reduction
A6: 20,000-49,999 meters | B6: 0.3 | C6: 1400 | D6: Additional 15%
A7: 50,000+ meters | B7: 0.45 | C7: 1100 | D7: Additional 15%
A10: Manufacturing Cost by Scenario
A12: Scenario | B12: Meters | C12: Cost per Meter (N$) | D12: Total Manufacturing Cost (N$)
A13: 3,000 Meters | B13: 3000 | C13: 2000 | D13: =B13*C13 -> 6000000
A14: 5,000 Meters | B14: 5000 | C14: 2000 | D14: =B14*C14 -> 10000000
A15: 10,000 Meters | B15: 10000 | C15: 1700 | D15: =B15*C15 -> 17000000
A16: 20,000 Meters | B16: 20000 | C16: 1700 | D16: =B16*C16 -> 34000000
A17: 50,000 Meters | B17: 50000 | C17: 1462 | D17: =B17*C17 -> 73100000

Sheet Revenue
A1: Revenue Model Assumptions
A3: Revenue Stream | B3: Rate | C3: Adoption Rate | D3: Calculation Basis | E3: Annual Amount per Meter (N$)
A4: Meter Hardware Sale | B4: N$5,500 (one-time) | C4: 1 | D4: One-time revenue per installed meter | E4: 5500
A5: Meter Installation Fee | B5: N$700 (one-time) | C5: 1 | D5: One-time fee per new meter installation | E5: 700
A6: Meter Maintenance | B6: N$500 / year | C6: 0.05 | D6: Annual maintenance fee on installed meters | E6: 25
A7: Wi-Fi Subscription | B7: N$25 / month | C7: 30% of installed base | D7: Recurring | E7: 90
A8: SMS Notifications | B8: N$2.50 / SMS | C8: 50% adoption, 2 SMS/month | D8: Recurring | E8: 30
A9: Mobile App Subscription | B9: N$65 / month | C9: 80% of installed base | D9: Recurring | E9: 624
A10: Real Estate Management Platform | B10: N$3,200 / block / month | C10: 1 block per 500 meters | D10: Recurring | E10: 76.8
A11: Total Year 1 Revenue per Meter | E11: =SUM(E4:E10) -> 7045.8
A14: Revenue by Year
A15: Year | B15: 3,000 Meters | C15: 5,000 Meters | D15: 10,000 Meters | E15: 20,000 Meters | F15: 50,000 Meters
A16: Year 1 | B16: =3000*E11 -> 21137400 | C16: =5000*E11 -> 35229000 | D16: =10000*E11 -> 70458000 | E16: =20000*E11 -> 140916000 | F16: =50000*E11 -> 352290000
A17: Year 2 | B17: =3000*(E6+E7+E8+E9+E10) -> 2537400 | C17: =5000*(E6+E7+E8+E9+E10) -> 4229000 | D17: =10000*(E6+E7+E8+E9+E10) -> 8458000 | E17: =20000*(E6+E7+E8+E9+E10) -> 16916000 | F17: =50000*(E6+E7+E8+E9+E10) -> 42290000
A18: Year 3 | B18: =3000*(E6+E7+E8+E9+E10) -> 2537400 | C18: =5000*(E6+E7+E8+E9+E10) -> 4229000 | D18: =10000*(E6+E7+E8+E9+E10) -> 8458000 | E18: =20000*(E6+E7+E8+E9+E10) -> 16916000 | F18: =50000*(E6+E7+E8+E9+E10) -> 42290000
A19: Year 4 | B19: =3000*(E6+E7+E8+E9+E10) -> 2537400 | C19: =5000*(E6+E7+E8+E9+E10) -> 4229000 | D19: =10000*(E6+E7+E8+E9+E10) -> 8458000 | E19: =20000*(E6+E7+E8+E9+E10) -> 16916000 | F19: =50000*(E6+E7+E8+E9+E10) -> 42290000
A20: Year 5 | B20: =3000*(E6+E7+E8+E9+E10) -> 2537400 | C20: =5000*(E6+E7+E8+E9+E10) -> 4229000 | D20: =10000*(E6+E7+E8+E9+E10) -> 8458000 | E20: =20000*(E6+E7+E8+E9+E10) -> 16916000 | F20: =50000*(E6+E7+E8+E9+E10) -> 42290000
A21: 5-Year Total | B21: =SUM(B16:B20) -> 31287000 | C21: =SUM(C16:C20) -> 52145000 | D21: =SUM(D16:D20) -> 104290000 | E21: =SUM(E16:E20) -> 208580000 | F21: =SUM(F16:F20) -> 521450000

Sheet Profitability Analysis
A1: Revenue & Profitability Analysis (Year 1)
A3: Metric | B3: 3,000 Meters | C3: 5,000 Meters | D3: 10,000 Meters | E3: 20,000 Meters | F3: 50,000 Meters
A4: REVENUE (N$)
A5: Hardware Sales | B5: =3000*Revenue!E4 -> 16500000 | C5: =5000*Revenue!E4 -> 27500000 | D5: =10000*Revenue!E4 -> 55000000 | E5: =20000*Revenue!E4 -> 110000000 | F5: =50000*Revenue!E4 -> 275000000
A6: Installation Fees | B6: =3000*Revenue!E5 -> 2100000 | C6: =5000*Revenue!E5 -> 3500000 | D6: =10000*Revenue!E5 -> 7000000 | E6: =20000*Revenue!E5 -> 14000000 | F6: =50000*Revenue!E5 -> 35000000
A7: Service Revenues | B7: =3000*(Revenue!E6+Revenue!E7+Revenue!E8+Revenue!E9+Revenue!E10) -> 2537400 | C7: =5000*(Revenue!E6+Revenue!E7+Revenue!E8+Revenue!E9+Revenue!E10) -> 4229000 | D7: =10000*(Revenue!E6+Revenue!E7+Revenue!E8+Revenue!E9+Revenue!E10) -> 8458000 | E7: =20000*(Revenue!E6+Revenue!E7+Revenue!E8+Revenue!E9+Revenue!E10) -> 16916000 | F7: =50000*(Revenue!E6+Revenue!E7+Revenue!E8+Revenue!E9+Revenue!E10) -> 42290000
A8: Total Revenue | B8: =SUM(B5:B7) -> 21137400 | C8: =SUM(C5:C7) -> 35229000 | D8: =SUM(D5:D7) -> 70458000 | E8: =SUM(E5:E7) -> 140916000 | F8: =SUM(F5:F7) -> 352290000
A9: MANUFACTURING COST (N$)
A10: Cost per Meter | B10: ='Manufacturing Cost'!C13 -> 2000 | C10: ='Manufacturing Cost'!C14 -> 2000 | D10: ='Manufacturing Cost'!C15 -> 1700 | E10: ='Manufacturing Cost'!C16 -> 1700 | F10: ='Manufacturing Cost'!C17 -> 1462
A11: Total Manufacturing Cost | B11: ='Manufacturing Cost'!D13 -> 6000000 | C11: ='Manufacturing Cost'!D14 -> 10000000 | D11: ='Manufacturing Cost'!D15 -> 17000000 | E11: ='Manufacturing Cost'!D16 -> 34000000 | F11: ='Manufacturing Cost'!D17 -> 73100000
A12: OPERATING COSTS (N$) | B12: ='Personnel Cost'!C91+'Infrastructure & Equipment'!C7 -> 1106400 | C12: ='Personnel Cost'!D91+'Infrastructure & Equipment'!D7 -> 2980800 | D12: ='Personnel Cost'!E91+'Infrastructure & Equipment'!E7 -> 5980800 | E12: ='Personnel Cost'!F91+'Infrastructure & Equipment'!F7 -> 8733600 | F12: ='Personnel Cost'!G91+'Infrastructure & Equipment'!G7 -> 13051200
A13: EQUIPMENT INVESTMENT (N$) | B13: ='Infrastructure & Equipment'!C19 -> 949700 | C13: ='Infrastructure & Equipment'!D19 -> 1739500 | D13: ='Infrastructure & Equipment'!E19 -> 3179000 | E13: ='Infrastructure & Equipment'!F19 -> 5038000 | F13: ='Infrastructure & Equipment'!G19 -> 10225000
A14: PROFITABILITY (N$)
A15: Gross Profit | B15: =B8-B11 -> 15137400 | C15: =C8-C11 -> 25229000 | D15: =D8-D11 -> 53458000 | E15: =E8-E11 -> 106916000 | F15: =F8-F11 -> 279190000
A16: Operating Profit (EBITDA) | B16: =B15-B12-B13 -> 13081300 | C16: =C15-C12-C13 -> 20508700 | D16: =D15-D12-D13 -> 44298200 | E16: =E15-E12-E13 -> 93144400 | F16: =F15-F12-F13 -> 255913800
A17: Net Profit | B17: =B16 -> 13081300 | C17: =C16 -> 20508700 | D17: =D16 -> 44298200 | E17: =E16 -> 93144400 | F17: =F16 -> 255913800
A18: MARGINS
A19: Gross Margin % | B19: =IF(B8<>0,B15/B8,0) -> 0.71614295 | C19: =IF(C8<>0,C15/C8,0) -> 0.71614295 | D19: =IF(D8<>0,D15/D8,0) -> 0.75872151 | E19: =IF(E8<>0,E15/E8,0) -> 0.75872151 | F19: =IF(F8<>0,F15/F8,0) -> 0.7925005
A20: Operating Margin % | B20: =IF(B8<>0,B16/B8,0) -> 0.61886987 | C20: =IF(C8<>0,C16/C8,0) -> 0.58215391 | D20: =IF(D8<>0,D16/D8,0) -> 0.62871782 | E20: =IF(E8<>0,E16/E8,0) -> 0.66099236 | F20: =IF(F8<>0,F16/F8,0) -> 0.72642936
A21: Net Margin % | B21: =IF(B8<>0,B17/B8,0) -> 0.61886987 | C21: =IF(C8<>0,C17/C8,0) -> 0.58215391 | D21: =IF(D8<>0,D17/D8,0) -> 0.62871782 | E21: =IF(E8<>0,E17/E8,0) -> 0.66099236 | F21: =IF(F8<>0,F17/F8,0) -> 0.72642936
A23: 5-YEAR PROJECTIONS
A24: Metric | B24: 3,000 Meters | C24: 5,000 Meters | D24: 10,000 Meters | E24: 20,000 Meters | F24: 50,000 Meters
A25: 5-Year Total Revenue | B25: =Revenue!B21 -> 31287000 | C25: =Revenue!C21 -> 52145000 | D25: =Revenue!D21 -> 104290000 | E25: =Revenue!E21 -> 208580000 | F25: =Revenue!F21 -> 521450000
A26: 5-Year Total Costs | B26: =B11+B12*5+B13 -> 12481700 | C26: =C11+C12*5+C13 -> 26643500 | D26: =D11+D12*5+D13 -> 50083000 | E26: =E11+E12*5+E13 -> 82706000 | F26: =F11+F12*5+F13 -> 148581000
A27: 5-Year Net Profit | B27: =B25-B26 -> 18805300 | C27: =C25-C26 -> 25501500 | D27: =D25-D26 -> 54207000 | E27: =E25-E26 -> 125874000 | F27: =F25-F26 -> 372869000
A28: 5-Year ROI % | B28: =IF(B26<>0,B27/B26,0) -> 1.5066297 | C28: =IF(C26<>0,C27/C26,0) -> 0.95713776 | D28: =IF(D26<>0,D27/D26,0) -> 1.0823433 | E28: =IF(E26<>0,E27/E26,0) -> 1.5219452 | F28: =IF(F26<>0,F27/F26,0) -> 2.5095335
A29: 5-Year Net Margin % | B29: =IF(B25<>0,B27/B25,0) -> 0.60105795 | C29: =IF(C25<>0,C27/C25,0) -> 0.48904977 | D29: =IF(D25<>0,D27/D25,0) -> 0.51977179 | E29: =IF(E25<>0,E27/E25,0) -> 0.60348068 | F29: =IF(F25<>0,F27/F25,0) -> 0.71506185
