Workbook

Sheet Dashboard
B2: GRIDx Smart Meter — 5-Year Financial Model
B4: Input Parameters | E4: Total Revenue (5Y) | H4: Net Profit (5Y) | K4: Gross Margin | N4: Payback Period
B5: Meter Rollout: | E5: =INDEX($C$63:$G$63,1,$C$51) -> 338040000 | H5: =INDEX($C$62:$G$62,1,$C$51) -> 296045953 | K5: =INDEX($C$64:$G$64,1,$C$51) -> 0.87577196 | N5: =INDEX($C$65:$G$65,1,$C$51) -> 4.2
B6: 10,000 Meters
B8: Hardware Price | C8: Per Unit/Year
B9: 5500
B11: Installation Fee | C11: One-Time
B12: 700
B14: Manufacturing Cost | C14: Per Unit
B15: =INDEX($C$53:$G$53,1,$C$51) -> 1700
B17: Personnel (Annual) | C17: Per Year
B18: =748800 -> 748800
B20: Service Revenue | C20: Per Year
B21: =INDEX($C$52:$G$52,1,$C$51)*6620.8 -> 66208000
K22: Profit Margins
B23: Total 5Y Costs | C23: 5-Year | L23: Gross Margin | N23: =INDEX($C$64:$G$64,1,$C$51) -> 0.87577196
B24: =INDEX($C$61:$G$61,1,$C$51) -> 41994047 | L24: Operating Margin | N24: =IF(INDEX($C$63:$G$63,1,$C$51)>0,(INDEX($C$63:$G$63,1,$C$51)-INDEX($C$61:$G$61,1,$C$51))/INDEX($C$63:$G$63,1,$C$51),0) -> 0.87577196
L25: Net Margin | N25: =INDEX($C$64:$G$64,1,$C$51) -> 0.87577196
B26: Net Profit | C26: 5-Year
B27: =INDEX($C$62:$G$62,1,$C$51) -> 296045953 | K27: Payback Period
K28: =INDEX($C$65:$G$65,1,$C$51) -> 4.2
K30: Months
K31: Payback Period
B36: Scenario Comparison
B37: Metric | E37: 3K | G37: 5K | I37: 10K | K37: 20K | M37: 50K
B38: Total Revenue (5Y) | E38: =C63 -> 101412000 | G38: =D63 -> 169020000 | I38: =E63 -> 338040000 | K38: =F63 -> 676080000 | M38: =G63 -> 1690200000
B39: Total Costs (5Y) | E39: =C61 -> 27375747 | G39: =D61 -> 32329547 | I39: =E61 -> 41994047 | K39: =F61 -> 64218047 | M39: =G61 -> 118425047
B40: Net Profit (5Y) | E40: =C62 -> 74036253 | G40: =D62 -> 136690453 | I40: =E62 -> 296045953 | K40: =F62 -> 611861953 | M40: =G62 -> 1571774953
B41: Gross Margin | E41: =C64 -> 0.73005417 | G41: =D64 -> 0.80872354 | I41: =E64 -> 0.87577196 | K41: =F64 -> 0.90501413 | M41: =G64 -> 0.9299343
B42: Payback Period | E42: =C65 -> 7.6 | G42: =D65 -> 7.2 | I42: =E65 -> 4.2 | K42: =F65 -> 3.9 | M42: =G65 -> 3.5
B43: DCF Valuation | E43: =C66 -> 65500000 | G43: =D66 -> 119300000 | I43: =E66 -> 259647182 | K43: =F66 -> 538200000 | M43: =G66 -> 1390000000
B49: DATA AREA
C50: 3,000 Meters | D50: 5,000 Meters | E50: 10,000 Meters | F50: 20,000 Meters | G50: 50,000 Meters
B51: Index | C51: =MATCH($B$6,$C$50:$G$50,0) -> 3
C52: 3000 | D52: 5000 | E52: 10000 | F52: 20000 | G52: 50000
C53: 2000 | D53: 2000 | E53: 1700 | F53: 1700 | G53: 1462
C54: ='Cost Detail'!B7 -> 6269700 | D54: ='Cost Detail'!C7 -> 10449500 | E54: ='Cost Detail'!D7 -> 17899000 | F54: ='Cost Detail'!E7 -> 35798000 | G54: ='Cost Detail'!F7 -> 77595000
C55: ='Cost Detail'!B20 -> 8914000 | D55: ='Cost Detail'!C20 -> 9444000 | E55: ='Cost Detail'!D20 -> 10844000 | F55: ='Cost Detail'!E20 -> 13644000 | G55: ='Cost Detail'!F20 -> 21894000
C56: ='Cost Detail'!B28 -> 1500000 | D56: ='Cost Detail'!C28 -> 1500000 | E56: ='Cost Detail'!D28 -> 1500000 | F56: ='Cost Detail'!E28 -> 1500000 | G56: ='Cost Detail'!F28 -> 1500000
C57: ='Cost Detail'!B38 -> 1099000 | D57: ='Cost Detail'!C38 -> 1290000 | E57: ='Cost Detail'!D38 -> 1965000 | F57: ='Cost Detail'!E38 -> 3210000 | G57: ='Cost Detail'!F38 -> 6545000
...

Sheet Revenue
A1: Revenue Model — Per Meter Rates
A3: Revenue Stream | B3: Rate | C3: Adoption | D3: Basis | E3: Annual per Meter (N$)
A4: Meter Hardware Sale | B4: N$5,500 (annual) | C4: 100% | D4: Annual revenue per meter | E4: 5500
A5: Meter Installation Fee | B5: N$700 (one-time) | C5: 100% | D5: One-time per new meter | E5: 700
A6: Maintenance Fees | B6: N$300 / year | C6: 100% | D6: Annual maintenance | E6: 300
A7: Wi-Fi Subscription | B7: N$25 / month | C7: 30% | D7: 30% × N$25 × 12 | E7: 90
A8: SMS Notifications | B8: N$2.50 / SMS | C8: 50% | D8: 50% × 2 SMS × N$2.50 × 12 | E8: 30
A9: Mobile App Subscription | B9: N$65 / month | C9: 80% | D9: 80% × N$65 × 12 | E9: 624
A10: Real Estate Management | B10: N$3,200/block/mo | C10: 1 per 500m | D10: (meters÷500)×3200×12÷meters | E10: 76.8
A11: Annual Recurring per Meter | E11: =E4+E6+E7+E8+E9+E10 -> 6620.8
A12: Year 1 Total per Meter (incl. installation) | E12: =E11+E5 -> 7320.8
A15: 5-Year Revenue by Scenario
A17: Revenue Stream | B17: 3,000 Meters | C17: 5,000 Meters | D17: 10,000 Meters | E17: 20,000 Meters | F17: 50,000 Meters
A18: Hardware Sales | B18: 82500000 | C18: 137500000 | D18: 275000000 | E18: 550000000 | F18: 1375000000
A19: Installation Fees | B19: 2100000 | C19: 3500000 | D19: 7000000 | E19: 14000000 | F19: 35000000
A20: Maintenance Fees | B20: 4500000 | C20: 7500000 | D20: 15000000 | E20: 30000000 | F20: 75000000
A21: Wi-Fi Subscriptions | B21: 1350000 | C21: 2250000 | D21: 4500000 | E21: 9000000 | F21: 22500000
A22: SMS Notifications | B22: 450000 | C22: 750000 | D22: 1500000 | E22: 3000000 | F22: 7500000
A23: Mobile App Subscriptions | B23: 9360000 | C23: 15600000 | D23: 31200000 | E23: 62400000 | F23: 156000000
A24: Real Estate Management | B24: 1152000 | C24: 1920000 | D24: 3840000 | E24: 7680000 | F24: 19200000
A25: Total 5-Year Revenue | B25: =SUM(B18:B24) -> 101412000 | C25: =SUM(C18:C24) -> 169020000 | D25: =SUM(D18:D24) -> 338040000 | E25: =SUM(E18:E24) -> 676080000 | F25: =SUM(F18:F24) -> 1690200000

Sheet Cost Detail
A1: Complete Cost Structure — 5-Year Projections
A3: MANUFACTURING COSTS
A4: Cost Item | B4: 3,000 Meters | C4: 5,000 Meters | D4: 10,000 Meters | E4: 20,000 Meters | F4: 50,000 Meters
A5: Meter Hardware | B5: 6000000 | C5: 10000000 | D5: 17000000 | E5: 34000000 | F5: 73100000
A6: Spare Parts Inventory (2%) | B6: 269700 | C6: 449500 | D6: 899000 | E6: 1798000 | F6: 4495000
A7: Total Manufacturing | B7: =SUM(B5:B6) -> 6269700 | C7: =SUM(C5:C6) -> 10449500 | D7: =SUM(D5:D6) -> 17899000 | E7: =SUM(E5:E6) -> 35798000 | F7: =SUM(F5:F6) -> 77595000
A9: OPERATING COSTS (5-Year)
A10: Cost Item | B10: 3,000 Meters | C10: 5,000 Meters | D10: 10,000 Meters | E10: 20,000 Meters | F10: 50,000 Meters
A11: Personnel Costs (N$748,800/yr) | B11: 3744000 | C11: 3744000 | D11: 3744000 | E11: 3744000 | F11: 3744000
A12: Data Storage & Transmission | B12: 720000 | C12: 1200000 | D12: 2400000 | E12: 4800000 | F12: 12000000
A13: Service Vehicles Maintenance | B13: 300000 | C13: 300000 | D13: 450000 | E13: 750000 | F13: 1500000
A14: Field Equipment Maintenance | B14: 100000 | C14: 150000 | D14: 200000 | E14: 300000 | F14: 600000
A15: Office Rental & Utilities | B15: 1200000 | C15: 1200000 | D15: 1200000 | E15: 1200000 | F15: 1200000
A16: Software Licensing & Tools | B16: 600000 | C16: 600000 | D16: 600000 | E16: 600000 | F16: 600000
A17: Marketing & Customer Acquisition | B17: 1000000 | C17: 1000000 | D17: 1000000 | E17: 1000000 | F17: 1000000
A18: Regulatory & Compliance | B18: 500000 | C18: 500000 | D18: 500000 | E18: 500000 | F18: 500000
A19: Insurance | B19: 750000 | C19: 750000 | D19: 750000 | E19: 750000 | F19: 750000
A20: Total Operating Costs (5-Year) | B20: =SUM(B11:B19) -> 8914000 | C20: =SUM(C11:C19) -> 9444000 | D20: =SUM(D11:D19) -> 10844000 | E20: =SUM(E11:E19) -> 13644000 | F20: =SUM(F11:F19) -> 21894000
A22: IMPLEMENTATION COSTS (One-Time)
A23: Cost Item | B23: 3,000 Meters | C23: 5,000 Meters | D23: 10,000 Meters | E23: 20,000 Meters | F23: 50,000 Meters
A24: Project Management & Planning | B24: 500000 | C24: 500000 | D24: 500000 | E24: 500000 | F24: 500000
A25: Site Surveys & Assessments | B25: 300000 | C25: 300000 | D25: 300000 | E25: 300000 | F25: 300000
A26: Customer Onboarding & Training | B26: 250000 | C26: 250000 | D26: 250000 | E26: 250000 | F26: 250000
A27: Integration with Utility Systems | B27: 450000 | C27: 450000 | D27: 450000 | E27: 450000 | F27: 450000
A28: Total Implementation | B28: =SUM(B24:B27) -> 1500000 | C28: =SUM(C24:C27) -> 1500000 | D28: =SUM(D24:D27) -> 1500000 | E28: =SUM(E24:E27) -> 1500000 | F28: =SUM(F24:F27) -> 1500000
A30: EQUIPMENT INVESTMENT (One-Time)
A31: Cost Item | B31: 3,000 Meters | C31: 5,000 Meters | D31: 10,000 Meters | E31: 20,000 Meters | F31: 50,000 Meters
A32: Service Vehicles | B32: 500000 | C32: 500000 | D32: 750000 | E32: 1250000 | F32: 2500000
A33: Field Test Equipment Kits | B33: 170000 | C33: 255000 | D33: 340000 | E33: 510000 | F33: 1020000
A34: Workstations | B34: 45000 | C34: 75000 | D34: 105000 | E34: 180000 | F34: 375000
A35: Network Monitoring Systems | B35: 120000 | C35: 120000 | D35: 240000 | E35: 360000 | F35: 600000
A36: Office Equipment & Furniture | B36: 119000 | C36: 165000 | D36: 280000 | E36: 510000 | F36: 1200000
A37: Server/Cloud Infrastructure | B37: 145000 | C37: 175000 | D37: 250000 | E37: 400000 | F37: 850000
A38: Total Equipment | B38: =SUM(B32:B37) -> 1099000 | C38: =SUM(C32:C37) -> 1290000 | D38: =SUM(D32:D37) -> 1965000 | E38: =SUM(E32:E37) -> 3210000 | F38: =SUM(F32:F37) -> 6545000
A40: DEVELOPMENT COSTS
A41: Cost Item | B41: 3,000 Meters | C41: 5,000 Meters | D41: 10,000 Meters | E41: 20,000 Meters | F41: 50,000 Meters
A42: Electronics Manufacturing Development | B42: 312000 | C42: 312000 | D42: 312000 | E42: 312000 | F42: 312000
A43: Software Engineering (R&D) | B43: 777747 | C43: 777747 | D43: 777747 | E43: 777747 | F43: 777747
A44: Mobile Application Development | B44: 300000 | C44: 300000 | D44: 300000 | E44: 300000 | F44: 300000
A45: Hardware Firmware Development | B45: 2160000 | C45: 2160000 | D45: 2160000 | E45: 2160000 | F45: 2160000
...

Sheet 5 Year Model
A1: 5-Year Financial Model — Year-by-Year Projections
A2: Linked to scenario selected on Dashboard
A4: Metric | B4: Year 1 | C4: Year 2 | D4: Year 3 | E4: Year 4 | F4: Year 5 | G4: 5-Year Total
A5: REVENUE
A6: Hardware Sales | B6: =Dashboard!$C$52*5500 -> 16500000 | C6: =B6 -> 16500000 | D6: =B6 -> 16500000 | E6: =B6 -> 16500000 | F6: =B6 -> 16500000 | H6: =SUM(B6:G6) -> 82500000
A7: Installation Fees | B7: =Dashboard!$C$52*700 -> 2100000 | C7: 0 | D7: 0 | E7: 0 | F7: 0 | H7: =SUM(B7:G7) -> 2100000
A8: Maintenance Fees | B8: =Dashboard!$C$52*300 -> 900000 | C8: =B8 -> 900000 | D8: =B8 -> 900000 | E8: =B8 -> 900000 | F8: =B8 -> 900000 | H8: =SUM(B8:G8) -> 4500000
A9: Wi-Fi Subscriptions | B9: =Dashboard!$C$52*90 -> 270000 | C9: =B9 -> 270000 | D9: =B9 -> 270000 | E9: =B9 -> 270000 | F9: =B9 -> 270000 | H9: =SUM(B9:G9) -> 1350000
A10: SMS Notifications | B10: =Dashboard!$C$52*30 -> 90000 | C10: =B10 -> 90000 | D10: =B10 -> 90000 | E10: =B10 -> 90000 | F10: =B10 -> 90000 | H10: =SUM(B10:G10) -> 450000
A11: Mobile App Subscriptions | B11: =Dashboard!$C$52*624 -> 1872000 | C11: =B11 -> 1872000 | D11: =B11 -> 1872000 | E11: =B11 -> 1872000 | F11: =B11 -> 1872000 | H11: =SUM(B11:G11) -> 9360000
A12: Real Estate Management | B12: =Dashboard!$C$52*76.8 -> 230400 | C12: =B12 -> 230400 | D12: =B12 -> 230400 | E12: =B12 -> 230400 | F12: =B12 -> 230400 | H12: =SUM(B12:G12) -> 1152000
A13: Total Revenue | B13: =SUM(B6:B12) -> 21962400 | C13: =SUM(C6:C12) -> 19862400 | D13: =SUM(D6:D12) -> 19862400 | E13: =SUM(E6:E12) -> 19862400 | F13: =SUM(F6:F12) -> 19862400 | G13: =SUM(G6:G12) -> 0 | H13: =SUM(H6:H12) -> 101412000
A15: COSTS
A16: Manufacturing Costs | B16: =Dashboard!$C$54 -> 6269700 | C16: 0 | D16: 0 | E16: 0 | F16: 0 | H16: =SUM(B16:G16) -> 6269700
A17: Operating Costs | B17: =Dashboard!$C$55/5 -> 1782800 | C17: =B17 -> 1782800 | D17: =B17 -> 1782800 | E17: =B17 -> 1782800 | F17: =B17 -> 1782800 | H17: =SUM(B17:G17) -> 8914000
A18: Implementation Costs | B18: =Dashboard!$C$56 -> 1500000 | C18: 0 | D18: 0 | E18: 0 | F18: 0 | H18: =SUM(B18:G18) -> 1500000
A19: Equipment Investment | B19: =Dashboard!$C$57 -> 1099000 | C19: 0 | D19: 0 | E19: 0 | F19: 0 | H19: =SUM(B19:G19) -> 1099000
A20: Development Costs | B20: =Dashboard!$C$58 -> 7851647 | C20: 0 | D20: 0 | E20: 0 | F20: 0 | H20: =SUM(B20:G20) -> 7851647
A21: Financing Costs | B21: =Dashboard!$C$59 -> 700000 | C21: 0 | D21: 0 | E21: 0 | F21: 0 | H21: =SUM(B21:G21) -> 700000
A22: Contingency | B22: =Dashboard!$C$60/5 -> 208280 | C22: =B22 -> 208280 | D22: =B22 -> 208280 | E22: =B22 -> 208280 | F22: =B22 -> 208280 | H22: =SUM(B22:G22) -> 1041400
A23: Total Costs | B23: =SUM(B16:B22) -> 19411427 | C23: =SUM(C16:C22) -> 1991080 | D23: =SUM(D16:D22) -> 1991080 | E23: =SUM(E16:E22) -> 1991080 | F23: =SUM(F16:F22) -> 1991080 | G23: =SUM(G16:G22) -> 0 | H23: =SUM(H16:H22) -> 27375747
A24: NET PROFIT | B24: =B13-B23 -> 2550973 | C24: =C13-C23 -> 17871320 | D24: =D13-D23 -> 17871320 | E24: =E13-E23 -> 17871320 | F24: =F13-F23 -> 17871320 | G24: =G13-G23 -> 0 | H24: =H13-H23 -> 74036253
A26: Cumulative Revenue | B26: =B13 -> 21962400 | C26: =B26+C13 -> 41824800 | D26: =C26+D13 -> 61687200 | E26: =D26+E13 -> 81549600 | F26: =E26+F13 -> 101412000
A27: Cumulative Net Profit | B27: =B24 -> 2550973 | C27: =B27+C24 -> 20422293 | D27: =C27+D24 -> 38293613 | E27: =D27+E24 -> 56164933 | F27: =E27+F24 -> 74036253
